Workbook

Sheet Übersicht
A1: FurMark (Intel UHD 630): Gesamtauswertung je Treiber
A2: Mittelwerte über alle verwerteten Zyklen; Lastfenster vollständiges Plateau je Durchlauf, vom ersten bis zum letzten Messwert über der Schwelle (Median 185.8 s, 184.6 bis 187.6 s). Alle Zahlen sind Verweise auf das Blatt 'Zyklusvergleich'.
A4: Kennzahl | B4: ALT (31.0.101.2115) | K4: MITTEL (31.0.101.2135) | T4: NEU (31.0.101.2141)
B5: Mittel | C5: SD | D5: Varianz | E5: CV [%] | F5: Spannweite | G5: 95-%-KI unten | H5: 95-%-KI oben | I5: Median | J5: n | K5: Mittel | L5: SD | M5: Varianz | N5: CV [%] | O5: Spannweite | P5: 95-%-KI unten | Q5: 95-%-KI oben | R5: Median | S5: n | T5: Mittel | U5: SD | V5: Varianz | W5: CV [%] | X5: Spannweite | Y5: 95-%-KI unten | Z5: 95-%-KI oben | AA5: Median | AB5: n
A6: Leerlauf vor [W] | B6: =Zyklusvergleich!$B$17 | C6: =Zyklusvergleich!$B$18 | D6: =Zyklusvergleich!$B$19 | E6: =Zyklusvergleich!$B$27 | F6: =Zyklusvergleich!$B$20 | G6: =Zyklusvergleich!$B$22 | H6: =Zyklusvergleich!$B$23 | I6: =Zyklusvergleich!$B$24 | J6: =Zyklusvergleich!$B$16 | K6: =Zyklusvergleich!$C$17 | L6: =Zyklusvergleich!$C$18 | M6: =Zyklusvergleich!$C$19 | N6: =Zyklusvergleich!$C$27 | O6: =Zyklusvergleich!$C$20 | P6: =Zyklusvergleich!$C$22 | Q6: =Zyklusvergleich!$C$23 | R6: =Zyklusvergleich!$C$24 | S6: =Zyklusvergleich!$C$16 | T6: =Zyklusvergleich!$D$17 | U6: =Zyklusvergleich!$D$18 | V6: =Zyklusvergleich!$D$19 | W6: =Zyklusvergleich!$D$27 | X6: =Zyklusvergleich!$D$20 | Y6: =Zyklusvergleich!$D$22 | Z6: =Zyklusvergleich!$D$23 | AA6: =Zyklusvergleich!$D$24 | AB6: =Zyklusvergleich!$D$16
A7: Last Ø [W] | B7: =Zyklusvergleich!$B$44 | C7: =Zyklusvergleich!$B$45 | D7: =Zyklusvergleich!$B$46 | E7: =Zyklusvergleich!$B$54 | F7: =Zyklusvergleich!$B$47 | G7: =Zyklusvergleich!$B$49 | H7: =Zyklusvergleich!$B$50 | I7: =Zyklusvergleich!$B$51 | J7: =Zyklusvergleich!$B$43 | K7: =Zyklusvergleich!$C$44 | L7: =Zyklusvergleich!$C$45 | M7: =Zyklusvergleich!$C$46 | N7: =Zyklusvergleich!$C$54 | O7: =Zyklusvergleich!$C$47 | P7: =Zyklusvergleich!$C$49 | Q7: =Zyklusvergleich!$C$50 | R7: =Zyklusvergleich!$C$51 | S7: =Zyklusvergleich!$C$43 | T7: =Zyklusvergleich!$D$44 | U7: =Zyklusvergleich!$D$45 | V7: =Zyklusvergleich!$D$46 | W7: =Zyklusvergleich!$D$54 | X7: =Zyklusvergleich!$D$47 | Y7: =Zyklusvergleich!$D$49 | Z7: =Zyklusvergleich!$D$50 | AA7: =Zyklusvergleich!$D$51 | AB7: =Zyklusvergleich!$D$43
A8: Leerlauf nach [W] | B8: =Zyklusvergleich!$B$71 | C8: =Zyklusvergleich!$B$72 | D8: =Zyklusvergleich!$B$73 | E8: =Zyklusvergleich!$B$81 | F8: =Zyklusvergleich!$B$74 | G8: =Zyklusvergleich!$B$76 | H8: =Zyklusvergleich!$B$77 | I8: =Zyklusvergleich!$B$78 | J8: =Zyklusvergleich!$B$70 | K8: =Zyklusvergleich!$C$71 | L8: =Zyklusvergleich!$C$72 | M8: =Zyklusvergleich!$C$73 | N8: =Zyklusvergleich!$C$81 | O8: =Zyklusvergleich!$C$74 | P8: =Zyklusvergleich!$C$76 | Q8: =Zyklusvergleich!$C$77 | R8: =Zyklusvergleich!$C$78 | S8: =Zyklusvergleich!$C$70 | T8: =Zyklusvergleich!$D$71 | U8: =Zyklusvergleich!$D$72 | V8: =Zyklusvergleich!$D$73 | W8: =Zyklusvergleich!$D$81 | X8: =Zyklusvergleich!$D$74 | Y8: =Zyklusvergleich!$D$76 | Z8: =Zyklusvergleich!$D$77 | AA8: =Zyklusvergleich!$D$78 | AB8: =Zyklusvergleich!$D$70
A9: Leerlauf Ø [W] | B9: =Zyklusvergleich!$B$98 | C9: =Zyklusvergleich!$B$99 | D9: =Zyklusvergleich!$B$100 | E9: =Zyklusvergleich!$B$108 | F9: =Zyklusvergleich!$B$101 | G9: =Zyklusvergleich!$B$103 | H9: =Zyklusvergleich!$B$104 | I9: =Zyklusvergleich!$B$105 | J9: =Zyklusvergleich!$B$97 | K9: =Zyklusvergleich!$C$98 | L9: =Zyklusvergleich!$C$99 | M9: =Zyklusvergleich!$C$100 | N9: =Zyklusvergleich!$C$108 | O9: =Zyklusvergleich!$C$101 | P9: =Zyklusvergleich!$C$103 | Q9: =Zyklusvergleich!$C$104 | R9: =Zyklusvergleich!$C$105 | S9: =Zyklusvergleich!$C$97 | T9: =Zyklusvergleich!$D$98 | U9: =Zyklusvergleich!$D$99 | V9: =Zyklusvergleich!$D$100 | W9: =Zyklusvergleich!$D$108 | X9: =Zyklusvergleich!$D$101 | Y9: =Zyklusvergleich!$D$103 | Z9: =Zyklusvergleich!$D$104 | AA9: =Zyklusvergleich!$D$105 | AB9: =Zyklusvergleich!$D$97
A10: Mehrverbrauch Delta [W] | B10: =Zyklusvergleich!$B$125 | C10: =Zyklusvergleich!$B$126 | D10: =Zyklusvergleich!$B$127 | E10: =Zyklusvergleich!$B$135 | F10: =Zyklusvergleich!$B$128 | G10: =Zyklusvergleich!$B$130 | H10: =Zyklusvergleich!$B$131 | I10: =Zyklusvergleich!$B$132 | J10: =Zyklusvergleich!$B$124 | K10: =Zyklusvergleich!$C$125 | L10: =Zyklusvergleich!$C$126 | M10: =Zyklusvergleich!$C$127 | N10: =Zyklusvergleich!$C$135 | O10: =Zyklusvergleich!$C$128 | P10: =Zyklusvergleich!$C$130 | Q10: =Zyklusvergleich!$C$131 | R10: =Zyklusvergleich!$C$132 | S10: =Zyklusvergleich!$C$124 | T10: =Zyklusvergleich!$D$125 | U10: =Zyklusvergleich!$D$126 | V10: =Zyklusvergleich!$D$127 | W10: =Zyklusvergleich!$D$135 | X10: =Zyklusvergleich!$D$128 | Y10: =Zyklusvergleich!$D$130 | Z10: =Zyklusvergleich!$D$131 | AA10: =Zyklusvergleich!$D$132 | AB10: =Zyklusvergleich!$D$124
A11: Energie Lastfenster [Wh] | B11: =Zyklusvergleich!$B$152 | C11: =Zyklusvergleich!$B$153 | D11: =Zyklusvergleich!$B$154 | E11: =Zyklusvergleich!$B$162 | F11: =Zyklusvergleich!$B$155 | G11: =Zyklusvergleich!$B$157 | H11: =Zyklusvergleich!$B$158 | I11: =Zyklusvergleich!$B$159 | J11: =Zyklusvergleich!$B$151 | K11: =Zyklusvergleich!$C$152 | L11: =Zyklusvergleich!$C$153 | M11: =Zyklusvergleich!$C$154 | N11: =Zyklusvergleich!$C$162 | O11: =Zyklusvergleich!$C$155 | P11: =Zyklusvergleich!$C$157 | Q11: =Zyklusvergleich!$C$158 | R11: =Zyklusvergleich!$C$159 | S11: =Zyklusvergleich!$C$151 | T11: =Zyklusvergleich!$D$152 | U11: =Zyklusvergleich!$D$153 | V11: =Zyklusvergleich!$D$154 | W11: =Zyklusvergleich!$D$162 | X11: =Zyklusvergleich!$D$155 | Y11: =Zyklusvergleich!$D$157 | Z11: =Zyklusvergleich!$D$158 | AA11: =Zyklusvergleich!$D$159 | AB11: =Zyklusvergleich!$D$151
A12: CV innerhalb Last [%] | B12: =Zyklusvergleich!$B$179 | C12: =Zyklusvergleich!$B$180 | D12: =Zyklusvergleich!$B$181 | E12: =Zyklusvergleich!$B$189 | F12: =Zyklusvergleich!$B$182 | G12: =Zyklusvergleich!$B$184 | H12: =Zyklusvergleich!$B$185 | I12: =Zyklusvergleich!$B$186 | J12: =Zyklusvergleich!$B$178 | K12: =Zyklusvergleich!$C$179 | L12: =Zyklusvergleich!$C$180 | M12: =Zyklusvergleich!$C$181 | N12: =Zyklusvergleich!$C$189 | O12: =Zyklusvergleich!$C$182 | P12: =Zyklusvergleich!$C$184 | Q12: =Zyklusvergleich!$C$185 | R12: =Zyklusvergleich!$C$186 | S12: =Zyklusvergleich!$C$178 | T12: =Zyklusvergleich!$D$179 | U12: =Zyklusvergleich!$D$180 | V12: =Zyklusvergleich!$D$181 | W12: =Zyklusvergleich!$D$189 | X12: =Zyklusvergleich!$D$182 | Y12: =Zyklusvergleich!$D$184 | Z12: =Zyklusvergleich!$D$185 | AA12: =Zyklusvergleich!$D$186 | AB12: =Zyklusvergleich!$D$178
A13: Schwankung in der Last, SD [W] | B13: =Zyklusvergleich!$B$206 | C13: =Zyklusvergleich!$B$207 | D13: =Zyklusvergleich!$B$208 | E13: =Zyklusvergleich!$B$216 | F13: =Zyklusvergleich!$B$209 | G13: =Zyklusvergleich!$B$211 | H13: =Zyklusvergleich!$B$212 | I13: =Zyklusvergleich!$B$213 | J13: =Zyklusvergleich!$B$205 | K13: =Zyklusvergleich!$C$206 | L13: =Zyklusvergleich!$C$207 | M13: =Zyklusvergleich!$C$208 | N13: =Zyklusvergleich!$C$216 | O13: =Zyklusvergleich!$C$209 | P13: =Zyklusvergleich!$C$211 | Q13: =Zyklusvergleich!$C$212 | R13: =Zyklusvergleich!$C$213 | S13: =Zyklusvergleich!$C$205 | T13: =Zyklusvergleich!$D$206 | U13: =Zyklusvergleich!$D$207 | V13: =Zyklusvergleich!$D$208 | W13: =Zyklusvergleich!$D$216 | X13: =Zyklusvergleich!$D$209 | Y13: =Zyklusvergleich!$D$211 | Z13: =Zyklusvergleich!$D$212 | AA13: =Zyklusvergleich!$D$213 | AB13: =Zyklusvergleich!$D$205
A14: Schwankung im Leerlauf, SD [W] | B14: =Zyklusvergleich!$B$233 | C14: =Zyklusvergleich!$B$234 | D14: =Zyklusvergleich!$B$235 | E14: =Zyklusvergleich!$B$243 | F14: =Zyklusvergleich!$B$236 | G14: =Zyklusvergleich!$B$238 | H14: =Zyklusvergleich!$B$239 | I14: =Zyklusvergleich!$B$240 | J14: =Zyklusvergleich!$B$232 | K14: =Zyklusvergleich!$C$233 | L14: =Zyklusvergleich!$C$234 | M14: =Zyklusvergleich!$C$235 | N14: =Zyklusvergleich!$C$243 | O14: =Zyklusvergleich!$C$236 | P14: =Zyklusvergleich!$C$238 | Q14: =Zyklusvergleich!$C$239 | R14: =Zyklusvergleich!$C$240 | S14: =Zyklusvergleich!$C$232 | T14: =Zyklusvergleich!$D$233 | U14: =Zyklusvergleich!$D$234 | V14: =Zyklusvergleich!$D$235 | W14: =Zyklusvergleich!$D$243 | X14: =Zyklusvergleich!$D$236 | Y14: =Zyklusvergleich!$D$238 | Z14: =Zyklusvergleich!$D$239 | AA14: =Zyklusvergleich!$D$240 | AB14: =Zyklusvergleich!$D$232
A15: Lastspitze [W] | B15: =Zyklusvergleich!$B$260 | C15: =Zyklusvergleich!$B$261 | D15: =Zyklusvergleich!$B$262 | E15: =Zyklusvergleich!$B$270 | F15: =Zyklusvergleich!$B$263 | G15: =Zyklusvergleich!$B$265 | H15: =Zyklusvergleich!$B$266 | I15: =Zyklusvergleich!$B$267 | J15: =Zyklusvergleich!$B$259 | K15: =Zyklusvergleich!$C$260 | L15: =Zyklusvergleich!$C$261 | M15: =Zyklusvergleich!$C$262 | N15: =Zyklusvergleich!$C$270 | O15: =Zyklusvergleich!$C$263 | P15: =Zyklusvergleich!$C$265 | Q15: =Zyklusvergleich!$C$266 | R15: =Zyklusvergleich!$C$267 | S15: =Zyklusvergleich!$C$259 | T15: =Zyklusvergleich!$D$260 | U15: =Zyklusvergleich!$D$261 | V15: =Zyklusvergleich!$D$262 | W15: =Zyklusvergleich!$D$270 | X15: =Zyklusvergleich!$D$263 | Y15: =Zyklusvergleich!$D$265 | Z15: =Zyklusvergleich!$D$266 | AA15: =Zyklusvergleich!$D$267 | AB15: =Zyklusvergleich!$D$259
A16: Einschwingspitze [W] | B16: =Zyklusvergleich!$B$287 | C16: =Zyklusvergleich!$B$288 | D16: =Zyklusvergleich!$B$289 | E16: =Zyklusvergleich!$B$297 | F16: =Zyklusvergleich!$B$290 | G16: =Zyklusvergleich!$B$292 | H16: =Zyklusvergleich!$B$293 | I16: =Zyklusvergleich!$B$294 | J16: =Zyklusvergleich!$B$286 | K16: =Zyklusvergleich!$C$287 | L16: =Zyklusvergleich!$C$288 | M16: =Zyklusvergleich!$C$289 | N16: =Zyklusvergleich!$C$297 | O16: =Zyklusvergleich!$C$290 | P16: =Zyklusvergleich!$C$292 | Q16: =Zyklusvergleich!$C$293 | R16: =Zyklusvergleich!$C$294 | S16: =Zyklusvergleich!$C$286 | T16: =Zyklusvergleich!$D$287 | U16: =Zyklusvergleich!$D$288 | V16: =Zyklusvergleich!$D$289 | W16: =Zyklusvergleich!$D$297 | X16: =Zyklusvergleich!$D$290 | Y16: =Zyklusvergleich!$D$292 | Z16: =Zyklusvergleich!$D$293 | AA16: =Zyklusvergleich!$D$294 | AB16: =Zyklusvergleich!$D$286
A17: FurMark-Score | B17: =Zyklusvergleich!$B$314 | C17: =Zyklusvergleich!$B$315 | D17: =Zyklusvergleich!$B$316 | E17: =Zyklusvergleich!$B$324 | F17: =Zyklusvergleich!$B$317 | G17: =Zyklusvergleich!$B$319 | H17: =Zyklusvergleich!$B$320 | I17: =Zyklusvergleich!$B$321 | J17: =Zyklusvergleich!$B$313 | K17: =Zyklusvergleich!$C$314 | L17: =Zyklusvergleich!$C$315 | M17: =Zyklusvergleich!$C$316 | N17: =Zyklusvergleich!$C$324 | O17: =Zyklusvergleich!$C$317 | P17: =Zyklusvergleich!$C$319 | Q17: =Zyklusvergleich!$C$320 | R17: =Zyklusvergleich!$C$321 | S17: =Zyklusvergleich!$C$313 | T17: =Zyklusvergleich!$D$314 | U17: =Zyklusvergleich!$D$315 | V17: =Zyklusvergleich!$D$316 | W17: =Zyklusvergleich!$D$324 | X17: =Zyklusvergleich!$D$317 | Y17: =Zyklusvergleich!$D$319 | Z17: =Zyklusvergleich!$D$320 | AA17: =Zyklusvergleich!$D$321 | AB17: =Zyklusvergleich!$D$313
A18: Effizienz [J je Score-Punkt] | B18: =Zyklusvergleich!$B$341 | C18: =Zyklusvergleich!$B$342 | D18: =Zyklusvergleich!$B$343 | E18: =Zyklusvergleich!$B$351 | F18: =Zyklusvergleich!$B$344 | G18: =Zyklusvergleich!$B$346 | H18: =Zyklusvergleich!$B$347 | I18: =Zyklusvergleich!$B$348 | J18: =Zyklusvergleich!$B$340 | K18: =Zyklusvergleich!$C$341 | L18: =Zyklusvergleich!$C$342 | M18: =Zyklusvergleich!$C$343 | N18: =Zyklusvergleich!$C$351 | O18: =Zyklusvergleich!$C$344 | P18: =Zyklusvergleich!$C$346 | Q18: =Zyklusvergleich!$C$347 | R18: =Zyklusvergleich!$C$348 | S18: =Zyklusvergleich!$C$340 | T18: =Zyklusvergleich!$D$341 | U18: =Zyklusvergleich!$D$342 | V18: =Zyklusvergleich!$D$343 | W18: =Zyklusvergleich!$D$351 | X18: =Zyklusvergleich!$D$344 | Y18: =Zyklusvergleich!$D$346 | Z18: =Zyklusvergleich!$D$347 | AA18: =Zyklusvergleich!$D$348 | AB18: =Zyklusvergleich!$D$340
A21: Rangfolge nach Mehrverbrauch unter Last (1 = sparsamster Treiber)
A22: Treiber | B22: Delta Mittel [W] | C22: Rang | D22: Abstand zum sparsamsten [W] | E22: Zyklen mit kleinstem Delta
A23: ALT (31.0.101.2115) | B23: =Zyklusvergleich!$B$125 | C23: =IF(B23="","",RANK(B23,$B$23:$B$25,1)) | D23: =IF(B23="","",B23-MIN($B$23:$B$25)) | E23: =Zyklusvergleich!$B$136
A24: MITTEL (31.0.101.2135) | B24: =Zyklusvergleich!$C$125 | C24: =IF(B24="","",RANK(B24,$B$23:$B$25,1)) | D24: =IF(B24="","",B24-MIN($B$23:$B$25)) | E24: =Zyklusvergleich!$C$136
A25: NEU (31.0.101.2141) | B25: =Zyklusvergleich!$D$125 | C25: =IF(B25="","",RANK(B25,$B$23:$B$25,1)) | D25: =IF(B25="","",B25-MIN($B$23:$B$25)) | E25: =Zyklusvergleich!$D$136
A28: Erläuterung der Spalten
A29: Mittel | B29: Mittelwert über alle verwerteten Zyklen.
A30: SD | B30: Standardabweichung: typische Abweichung eines einzelnen Zyklus vom Mittelwert, in der Einheit der Kennzahl. Klein = Treiber verhält sich von Zyklus zu Zyklus gleich.
A31: Varianz | B31: Quadrat der SD (Einheit zum Quadrat, z. B. W²). Gleiche Aussage wie die SD, aber schwerer zu deuten; Grundlage vieler statistischer Tests.
A32: CV [%] | B32: Variationskoeffizient = SD / Mittelwert × 100. Relative Streuung; vergleichbar zwischen Treibern und Kennzahlen mit unterschiedlichem Niveau.
A33: Spannweite | B33: Größter minus kleinster Zykluswert: die gesamte beobachtete Schwankungsbreite.
A34: 95-%-KI unten/oben | B34: Konfidenzintervall des MITTELWERTS: Bereich, in dem der wahre Mittelwert mit 95 % Sicherheit liegt. Beschreibt die Genauigkeit des Mittelwerts, nicht die Schwankung der Einzelwerte. Überlappen sich die Intervalle zweier Treiber nicht, unterscheiden sie sich deutlich.
A35: Median | B35: mittlerer Wert der sortierten Zykluswerte, unempfindlich gegen Ausreißer.
A36: n | B36: Anzahl verwerteter Zyklen.

Sheet Stabilität
A1: FurMark (Intel UHD 630): Stabilität der Treiber
A2: Innerhalb = wie ruhig die Leistung während einer Phase ist (Mittel über die Zyklen). Zwischen = wie gut sich das Zyklusergebnis wiederholt. Kleinere Werte = stabiler. Alle Zahlen sind Verweise auf 'Zyklusvergleich'.
A4: Treiber | B4: SD in der Last [W] | C4: CV in der Last [%] | D4: SD im Leerlauf [W] | E4: Last Ø: SD zw. Zyklen [W] | F4: Last Ø: Varianz [W²] | G4: Last Ø: CV zw. Zyklen [%] | H4: Last Ø: Spannweite [W] | I4: Delta: SD zw. Zyklen [W] | J4: Delta: Varianz [W²] | K4: Delta: CV zw. Zyklen [%] | L4: Delta: Spannweite [W] | M4: Rang Ruhe in der Last (1 = ruhigste) | N4: Rang Wiederholbarkeit Last (1 = stabilste)
A5: ALT (31.0.101.2115) | B5: =Zyklusvergleich!$B$206 | C5: =Zyklusvergleich!$B$179 | D5: =Zyklusvergleich!$B$233 | E5: =Zyklusvergleich!$B$45 | F5: =Zyklusvergleich!$B$46 | G5: =Zyklusvergleich!$B$54 | H5: =Zyklusvergleich!$B$47 | I5: =Zyklusvergleich!$B$126 | J5: =Zyklusvergleich!$B$127 | K5: =Zyklusvergleich!$B$135 | L5: =Zyklusvergleich!$B$128 | M5: =IF(C5="","",RANK(C5,$C$5:$C$7,1)) | N5: =IF(G5="","",RANK(G5,$G$5:$G$7,1))
A6: MITTEL (31.0.101.2135) | B6: =Zyklusvergleich!$C$206 | C6: =Zyklusvergleich!$C$179 | D6: =Zyklusvergleich!$C$233 | E6: =Zyklusvergleich!$C$45 | F6: =Zyklusvergleich!$C$46 | G6: =Zyklusvergleich!$C$54 | H6: =Zyklusvergleich!$C$47 | I6: =Zyklusvergleich!$C$126 | J6: =Zyklusvergleich!$C$127 | K6: =Zyklusvergleich!$C$135 | L6: =Zyklusvergleich!$C$128 | M6: =IF(C6="","",RANK(C6,$C$5:$C$7,1)) | N6: =IF(G6="","",RANK(G6,$G$5:$G$7,1))
A7: NEU (31.0.101.2141) | B7: =Zyklusvergleich!$D$206 | C7: =Zyklusvergleich!$D$179 | D7: =Zyklusvergleich!$D$233 | E7: =Zyklusvergleich!$D$45 | F7: =Zyklusvergleich!$D$46 | G7: =Zyklusvergleich!$D$54 | H7: =Zyklusvergleich!$D$47 | I7: =Zyklusvergleich!$D$126 | J7: =Zyklusvergleich!$D$127 | K7: =Zyklusvergleich!$D$135 | L7: =Zyklusvergleich!$D$128 | M7: =IF(C7="","",RANK(C7,$C$5:$C$7,1)) | N7: =IF(G7="","",RANK(G7,$G$5:$G$7,1))
A10: Unterscheidet sich die Stabilität signifikant?
A11: Berechnet in Python mit scipy. Innerhalb: Kruskal-Wallis und Welch-Test auf die SD je Zyklus. Zwischen: Brown-Forsythe-Test (Levene mit Median) auf Gleichheit der Streuung. Paarweise p-Werte Holm-korrigiert.
A13: Prüfgröße | B13: Test | C13: p global | D13: Vergleich | E13: Kennwert | F13: p (Holm) | G13: signifikant (5 %)
A14: Schwankung innerhalb der Last (SD je Zyklus) | B14: Kruskal-Wallis / Welch | C14: 0.67118553 | D14: MITTEL (31.0.101.2135) vs. ALT (31.0.101.2115) | E14: 0.11651748 | F14: 0.78269592 | G14: =IF(F14="","",IF(F14<0.05,"ja","nein"))
A15: Schwankung innerhalb der Last (SD je Zyklus) | B15: Kruskal-Wallis / Welch | C15: 0.67118553 | D15: NEU (31.0.101.2141) vs. ALT (31.0.101.2115) | E15: 0.13663311 | F15: 0.78269592 | G15: =IF(F15="","",IF(F15<0.05,"ja","nein"))
A16: Schwankung innerhalb der Last (SD je Zyklus) | B16: Kruskal-Wallis / Welch | C16: 0.67118553 | D16: NEU (31.0.101.2141) vs. MITTEL (31.0.101.2135) | E16: 0.020115627 | F16: 0.89026974 | G16: =IF(F16="","",IF(F16<0.05,"ja","nein"))
A17: Wiederholbarkeit Last Ø zwischen den Zyklen | B17: Brown-Forsythe (Levene, Median) | C17: 0.7076281 | D17: MITTEL (31.0.101.2135) vs. ALT (31.0.101.2115) | E17: 0.54129567 | F17: 1 | G17: =IF(F17="","",IF(F17<0.05,"ja","nein"))
A18: Wiederholbarkeit Last Ø zwischen den Zyklen | B18: Brown-Forsythe (Levene, Median) | C18: 0.7076281 | D18: NEU (31.0.101.2141) vs. ALT (31.0.101.2115) | E18: 0.64335461 | F18: 1 | G18: =IF(F18="","",IF(F18<0.05,"ja","nein"))
A19: Wiederholbarkeit Last Ø zwischen den Zyklen | B19: Brown-Forsythe (Levene, Median) | C19: 0.7076281 | D19: NEU (31.0.101.2141) vs. MITTEL (31.0.101.2135) | E19: 1.1885456 | F19: 1 | G19: =IF(F19="","",IF(F19<0.05,"ja","nein"))
A20: Wiederholbarkeit Mehrverbrauch zwischen den Zyklen | B20: Brown-Forsythe (Levene, Median) | C20: 0.46546326 | D20: MITTEL (31.0.101.2135) vs. ALT (31.0.101.2115) | E20: 2.0431273 | F20: 0.86332956 | G20: =IF(F20="","",IF(F20<0.05,"ja","nein"))
A21: Wiederholbarkeit Mehrverbrauch zwischen den Zyklen | B21: Brown-Forsythe (Levene, Median) | C21: 0.46546326 | D21: NEU (31.0.101.2141) vs. ALT (31.0.101.2115) | E21: 3.3555634 | F21: 0.76849904 | G21: =IF(F21="","",IF(F21<0.05,"ja","nein"))
A22: Wiederholbarkeit Mehrverbrauch zwischen den Zyklen | B22: Brown-Forsythe (Levene, Median) | C22: 0.46546326 | D22: NEU (31.0.101.2141) vs. MITTEL (31.0.101.2135) | E22: 1.6423663 | F22: 0.86332956 | G22: =IF(F22="","",IF(F22<0.05,"ja","nein"))
A24: Kennwert: bei 'innerhalb' die Differenz der mittleren SD (B − A, in W); bei 'Wiederholbarkeit' das Verhältnis der SD (B / A, 2 = doppelt so starke Streuung).

Sheet Zyklusvergleich
A1: FurMark (Intel UHD 630): zyklusweiser Treibervergleich
A2: Leere Zelle = Zyklus nicht verwertet (Grund in 'Hinweis'). Die grau hinterlegten Kennzahlen sind Formeln über die verwerteten Zyklen; grün = kleinster Wert im Zyklus.
A4: Leerlauf vor [W]
A5: Zyklus | B5: ALT (31.0.101.2115) | C5: MITTEL (31.0.101.2135) | D5: NEU (31.0.101.2141) | E5: Kleinster Wert | F5: MITTEL (31.0.101.2135) − ALT (31.0.101.2115) | G5: NEU (31.0.101.2141) − ALT (31.0.101.2115) | H5: Hinweis
A6: 1 | B6: 9.147433 | C6: 10.651241 | D6: 12.13915 | E6: =IF(COUNT(B6:D6)=0,"",INDEX($B$5:$D$5,MATCH(MIN(B6:D6),B6:D6,0))) | F6: =IF(OR(C6="",B6=""),"",C6-B6) | G6: =IF(OR(D6="",B6=""),"",D6-B6)
A7: 2 | B7: 9.025096 | C7: 8.150762 | D7: 9.028005 | E7: =IF(COUNT(B7:D7)=0,"",INDEX($B$5:$D$5,MATCH(MIN(B7:D7),B7:D7,0))) | F7: =IF(OR(C7="",B7=""),"",C7-B7) | G7: =IF(OR(D7="",B7=""),"",D7-B7)
A8: 3 | B8: 9.368393 | C8: 8.140231 | D8: 8.514878 | E8: =IF(COUNT(B8:D8)=0,"",INDEX($B$5:$D$5,MATCH(MIN(B8:D8),B8:D8,0))) | F8: =IF(OR(C8="",B8=""),"",C8-B8) | G8: =IF(OR(D8="",B8=""),"",D8-B8)
A9: 4 | B9: 9.359268 | C9: 7.891929 | D9: 8.111393 | E9: =IF(COUNT(B9:D9)=0,"",INDEX($B$5:$D$5,MATCH(MIN(B9:D9),B9:D9,0))) | F9: =IF(OR(C9="",B9=""),"",C9-B9) | G9: =IF(OR(D9="",B9=""),"",D9-B9)
A10: 5 | B10: 9.514107 | C10: 7.9202 | D10: 8.047008 | E10: =IF(COUNT(B10:D10)=0,"",INDEX($B$5:$D$5,MATCH(MIN(B10:D10),B10:D10,0))) | F10: =IF(OR(C10="",B10=""),"",C10-B10) | G10: =IF(OR(D10="",B10=""),"",D10-B10)
A11: 6 | B11: 9.385518 | C11: 8.081882 | D11: 7.792365 | E11: =IF(COUNT(B11:D11)=0,"",INDEX($B$5:$D$5,MATCH(MIN(B11:D11),B11:D11,0))) | F11: =IF(OR(C11="",B11=""),"",C11-B11) | G11: =IF(OR(D11="",B11=""),"",D11-B11)
A12: 7 | B12: 9.478637 | C12: 7.898133 | D12: 7.798911 | E12: =IF(COUNT(B12:D12)=0,"",INDEX($B$5:$D$5,MATCH(MIN(B12:D12),B12:D12,0))) | F12: =IF(OR(C12="",B12=""),"",C12-B12) | G12: =IF(OR(D12="",B12=""),"",D12-B12)
A13: 8 | B13: 9.237428 | C13: 7.755428 | D13: 7.969583 | E13: =IF(COUNT(B13:D13)=0,"",INDEX($B$5:$D$5,MATCH(MIN(B13:D13),B13:D13,0))) | F13: =IF(OR(C13="",B13=""),"",C13-B13) | G13: =IF(OR(D13="",B13=""),"",D13-B13)
A14: 9 | B14: 8.916174 | C14: 7.941778 | D14: 7.843114 | E14: =IF(COUNT(B14:D14)=0,"",INDEX($B$5:$D$5,MATCH(MIN(B14:D14),B14:D14,0))) | F14: =IF(OR(C14="",B14=""),"",C14-B14) | G14: =IF(OR(D14="",B14=""),"",D14-B14)
A15: 10 | B15: 9.332764 | C15: 7.560388 | D15: 8.06065 | E15: =IF(COUNT(B15:D15)=0,"",INDEX($B$5:$D$5,MATCH(MIN(B15:D15),B15:D15,0))) | F15: =IF(OR(C15="",B15=""),"",C15-B15) | G15: =IF(OR(D15="",B15=""),"",D15-B15)
A16: n | B16: =COUNT(B6:B15) | C16: =COUNT(C6:C15) | D16: =COUNT(D6:D15) | F16: =COUNT(F6:F15) | G16: =COUNT(G6:G15)
A17: Mittelwert | B17: =IF(B16=0,"",AVERAGE(B6:B15)) | C17: =IF(C16=0,"",AVERAGE(C6:C15)) | D17: =IF(D16=0,"",AVERAGE(D6:D15)) | F17: =IF(F16=0,"",AVERAGE(F6:F15)) | G17: =IF(G16=0,"",AVERAGE(G6:G15))
A18: Standardabweichung | B18: =IF(B16<2,"",STDEV(B6:B15)) | C18: =IF(C16<2,"",STDEV(C6:C15)) | D18: =IF(D16<2,"",STDEV(D6:D15)) | F18: =IF(F16<2,"",STDEV(F6:F15)) | G18: =IF(G16<2,"",STDEV(G6:G15))
A19: Varianz | B19: =IF(B16<2,"",VAR(B6:B15)) | C19: =IF(C16<2,"",VAR(C6:C15)) | D19: =IF(D16<2,"",VAR(D6:D15)) | F19: =IF(F16<2,"",VAR(F6:F15)) | G19: =IF(G16<2,"",VAR(G6:G15))
A20: Spannweite | B20: =IF(B16=0,"",MAX(B6:B15)-MIN(B6:B15)) | C20: =IF(C16=0,"",MAX(C6:C15)-MIN(C6:C15)) | D20: =IF(D16=0,"",MAX(D6:D15)-MIN(D6:D15)) | F20: =IF(F16=0,"",MAX(F6:F15)-MIN(F6:F15)) | G20: =IF(G16=0,"",MAX(G6:G15)-MIN(G6:G15))
A21: 95-%-KI ± | B21: =IF(B16<2,"",TINV(0.05,B16-1)*B18/SQRT(B16)) | C21: =IF(C16<2,"",TINV(0.05,C16-1)*C18/SQRT(C16)) | D21: =IF(D16<2,"",TINV(0.05,D16-1)*D18/SQRT(D16)) | F21: =IF(F16<2,"",TINV(0.05,F16-1)*F18/SQRT(F16)) | G21: =IF(G16<2,"",TINV(0.05,G16-1)*G18/SQRT(G16))
A22: KI unten | B22: =IF(B16<2,"",B17-B21) | C22: =IF(C16<2,"",C17-C21) | D22: =IF(D16<2,"",D17-D21) | F22: =IF(F16<2,"",F17-F21) | G22: =IF(G16<2,"",G17-G21)
A23: KI oben | B23: =IF(B16<2,"",B17+B21) | C23: =IF(C16<2,"",C17+C21) | D23: =IF(D16<2,"",D17+D21) | F23: =IF(F16<2,"",F17+F21) | G23: =IF(G16<2,"",G17+G21)
A24: Median | B24: =IF(B16=0,"",MEDIAN(B6:B15)) | C24: =IF(C16=0,"",MEDIAN(C6:C15)) | D24: =IF(D16=0,"",MEDIAN(D6:D15)) | F24: =IF(F16=0,"",MEDIAN(F6:F15)) | G24: =IF(G16=0,"",MEDIAN(G6:G15))
A25: Minimum | B25: =IF(B16=0,"",MIN(B6:B15)) | C25: =IF(C16=0,"",MIN(C6:C15)) | D25: =IF(D16=0,"",MIN(D6:D15)) | F25: =IF(F16=0,"",MIN(F6:F15)) | G25: =IF(G16=0,"",MIN(G6:G15))
A26: Maximum | B26: =IF(B16=0,"",MAX(B6:B15)) | C26: =IF(C16=0,"",MAX(C6:C15)) | D26: =IF(D16=0,"",MAX(D6:D15)) | F26: =IF(F16=0,"",MAX(F6:F15)) | G26: =IF(G16=0,"",MAX(G6:G15))
A27: CV zw. Zyklen [%] | B27: =IF(OR(B16<2,B17=0),"",B18/ABS(B17)*100) | C27: =IF(OR(C16<2,C17=0),"",C18/ABS(C17)*100) | D27: =IF(OR(D16<2,D17=0),"",D18/ABS(D17)*100)
A28: Zyklen mit kleinstem Wert | B28: =COUNTIF($E$6:$E$15,B$5) | C28: =COUNTIF($E$6:$E$15,C$5) | D28: =COUNTIF($E$6:$E$15,D$5)
A31: Last Ø [W]
A32: Zyklus | B32: ALT (31.0.101.2115) | C32: MITTEL (31.0.101.2135) | D32: NEU (31.0.101.2141) | E32: Kleinster Wert | F32: MITTEL (31.0.101.2135) − ALT (31.0.101.2115) | G32: NEU (31.0.101.2141) − ALT (31.0.101.2115) | H32: Hinweis
A33: 1 | B33: 53.48885 | C33: 52.90871 | D33: 52.943579 | E33: =IF(COUNT(B33:D33)=0,"",INDEX($B$32:$D$32,MATCH(MIN(B33:D33),B33:D33,0))) | F33: =IF(OR(C33="",B33=""),"",C33-B33) | G33: =IF(OR(D33="",B33=""),"",D33-B33)
A34: 2 | B34: 54.291434 | C34: 52.904609 | D34: 53.540438 | E34: =IF(COUNT(B34:D34)=0,"",INDEX($B$32:$D$32,MATCH(MIN(B34:D34),B34:D34,0))) | F34: =IF(OR(C34="",B34=""),"",C34-B34) | G34: =IF(OR(D34="",B34=""),"",D34-B34)
A35: 3 | B35: 54.175158 | C35: 53.366874 | D35: 53.384918 | E35: =IF(COUNT(B35:D35)=0,"",INDEX($B$32:$D$32,MATCH(MIN(B35:D35),B35:D35,0))) | F35: =IF(OR(C35="",B35=""),"",C35-B35) | G35: =IF(OR(D35="",B35=""),"",D35-B35)
A36: 4 | B36: 54.176452 | C36: 53.15146 | D36: 53.127947 | E36: =IF(COUNT(B36:D36)=0,"",INDEX($B$32:$D$32,MATCH(MIN(B36:D36),B36:D36,0))) | F36: =IF(OR(C36="",B36=""),"",C36-B36) | G36: =IF(OR(D36="",B36=""),"",D36-B36)
A37: 5 | B37: 54.371071 | C37: 53.14168 | D37: 53.176139 | E37: =IF(COUNT(B37:D37)=0,"",INDEX($B$32:$D$32,MATCH(MIN(B37:D37),B37:D37,0))) | F37: =IF(OR(C37="",B37=""),"",C37-B37) | G37: =IF(OR(D37="",B37=""),"",D37-B37)
A38: 6 | B38: 54.354964 | C38: 53.224609 | D38: 53.288747 | E38: =IF(COUNT(B38:D38)=0,"",INDEX($B$32:$D$32,MATCH(MIN(B38:D38),B38:D38,0))) | F38: =IF(OR(C38="",B38=""),"",C38-B38) | G38: =IF(OR(D38="",B38=""),"",D38-B38)
A39: 7 | B39: 53.825072 | C39: 53.051459 | D39: 53.015039 | E39: =IF(COUNT(B39:D39)=0,"",INDEX($B$32:$D$32,MATCH(MIN(B39:D39),B39:D39,0))) | F39: =IF(OR(C39="",B39=""),"",C39-B39) | G39: =IF(OR(D39="",B39=""),"",D39-B39)
A40: 8 | B40: 54.178304 | C40: 53.109639 | D40: 53.271356 | E40: =IF(COUNT(B40:D40)=0,"",INDEX($B$32:$D$32,MATCH(MIN(B40:D40),B40:D40,0))) | F40: =IF(OR(C40="",B40=""),"",C40-B40) | G40: =IF(OR(D40="",B40=""),"",D40-B40)
A41: 9 | B41: 54.085593 | C41: 53.140264 | D41: 53.191089 | E41: =IF(COUNT(B41:D41)=0,"",INDEX($B$32:$D$32,MATCH(MIN(B41:D41),B41:D41,0))) | F41: =IF(OR(C41="",B41=""),"",C41-B41) | G41: =IF(OR(D41="",B41=""),"",D41-B41)
A42: 10 | B42: 54.163098 | C42: 52.961753 | D42: 53.20098 | E42: =IF(COUNT(B42:D42)=0,"",INDEX($B$32:$D$32,MATCH(MIN(B42:D42),B42:D42,0))) | F42: =IF(OR(C42="",B42=""),"",C42-B42) | G42: =IF(OR(D42="",B42=""),"",D42-B42)
A43: n | B43: =COUNT(B33:B42) | C43: =COUNT(C33:C42) | D43: =COUNT(D33:D42) | F43: =COUNT(F33:F42) | G43: =COUNT(G33:G42)
...

Sheet Zyklen_Detail
A1: Treiber | B1: Zyklus | C1: Lastbeginn [min] | D1: Lastdauer [s] | E1: Abstand zum Vorzyklus [s] | F1: vollständig | G1: Ausreißer | H1: verwertet | I1: Leerlauf vor Ø [W] | J1: Leerlauf vor Median [W] | K1: Leerlauf nach Ø [W] | L1: Leerlauf nach Median [W] | M1: Leerlauf Ø [W] | N1: Leerlauf Median [W] | O1: Leerlauf nach − vor [W] | P1: Leerlaufspitzen [Anzahl] | Q1: größte Leerlaufspitze [W] | R1: Last Ø [W] | S1: Last Median [W] | T1: Last SD [W] | U1: CV Last [%] | V1: Last Max [W] | W1: Last P95 [W] | X1: Einschwingspitze [W] | Y1: Lastfenster [s] | Z1: Energie Lastfenster [Wh] | AA1: Delta (Mittelwerte) [W] | AB1: Delta (Mediane) [W] | AC1: FurMark-Score | AD1: Effizienz [J je Score-Punkt]
A2: ALT (31.0.101.2115) | B2: 1 | C2: 1.127416 | D2: 185.56137 | F2: ja | G2: nein | H2: ja | I2: 9.147433 | J2: 9.209168 | K2: 9.682521 | L2: 9.51396 | M2: 9.414977 | N2: 9.3312 | O2: 0.535088 | P2: 3 | Q2: 13.81728 | R2: 53.48885 | S2: 53.70624 | T2: 1.781525 | U2: 3.330647 | V2: 56.2596 | W2: 54.66192 | X2: 54.26973 | Y2: 185.56137 | Z2: 2.761189 | AA2: 44.073874 | AB2: 44.37504 | AC2: 1150 | AD2: 7.11166
A3: ALT (31.0.101.2115) | B3: 2 | C3: 6.25511 | D3: 184.59455 | E3: 307.66163 | F3: ja | G3: nein | H3: ja | I3: 9.025096 | J3: 9.15828 | K3: 9.117436 | L3: 9.110958 | M3: 9.071266 | N3: 9.15828 | O3: 0.09234 | P3: 0 | Q3: 12.84192 | R3: 54.291434 | S3: 54.23088 | T3: 1.627025 | U3: 2.996836 | V3: 62.0136 | W3: 55.95993 | X3: 53.8704 | Y3: 184.59455 | Z3: 2.785574 | AA3: 45.220168 | AB3: 45.0726 | AC3: 1148 | AD3: 7.271251
A4: ALT (31.0.101.2115) | B4: 3 | C4: 11.365782 | D4: 186.70708 | E4: 306.6403 | F4: ja | G4: nein | H4: ja | I4: 9.368393 | J4: 9.246672 | K4: 9.768391 | L4: 9.567941 | M4: 9.568392 | N4: 9.455231 | O4: 0.399998 | P4: 3 | Q4: 16.194236 | R4: 54.175158 | S4: 54.30888 | T4: 1.77676 | U4: 3.279659 | V4: 56.964688 | W4: 55.36746 | X4: 53.89272 | Y4: 186.70708 | Z4: 2.813999 | AA4: 44.606766 | AB4: 44.853649 | AC4: 1167 | AD4: 7.136589
A5: ALT (31.0.101.2115) | B5: 4 | C5: 16.495675 | D5: 185.65999 | E5: 307.79362 | F5: ja | G5: nein | H5: ja | I5: 9.359268 | J5: 9.375098 | K5: 9.544433 | L5: 9.50628 | M5: 9.451851 | N5: 9.403636 | O5: 0.185165 | P5: 1 | Q5: 19.882018 | R5: 54.176452 | S5: 54.346464 | T5: 1.742204 | U5: 3.215795 | V5: 57.7918 | W5: 55.656926 | X5: 53.923268 | Y5: 185.65999 | Z5: 2.797838 | AA5: 44.724601 | AB5: 44.942828 | AC5: 1158 | AD5: 7.170612
A6: ALT (31.0.101.2115) | B6: 5 | C6: 21.610054 | D6: 185.57621 | E6: 306.86273 | F6: ja | G6: nein | H6: ja | I6: 9.514107 | J6: 9.505014 | K6: 9.3872 | L6: 9.528588 | M6: 9.450654 | N6: 9.515574 | O6: -0.126907 | P6: 2 | Q6: 15.33576 | R6: 54.371071 | S6: 54.6324 | T6: 1.982943 | U6: 3.647055 | V6: 57.31584 | W6: 56.01936 | X6: 53.535258 | Y6: 185.57621 | Z6: 2.807587 | AA6: 44.920417 | AB6: 45.116826 | AC6: 1156 | AD6: 7.211212
A7: ALT (31.0.101.2115) | B7: 6 | C7: 26.722806 | D7: 185.85481 | E7: 306.7651 | F7: ja | G7: nein | H7: ja | I7: 9.385518 | J7: 9.50328 | K7: 9.341881 | L7: 9.450322 | M7: 9.363699 | N7: 9.477442 | O7: -0.043638 | P7: 0 | Q7: 12.268828 | R7: 54.354964 | S7: 54.5832 | T7: 1.913094 | U7: 3.519632 | V7: 56.8944 | W7: 55.390234 | X7: 54.843888 | Y7: 185.85481 | Z7: 2.808917 | AA7: 44.991264 | AB7: 45.105757 | AC7: 1161 | AD7: 7.202276
A8: ALT (31.0.101.2115) | B8: 7 | C8: 31.857685 | D8: 185.96257 | E8: 308.09272 | F8: ja | G8: nein | H8: ja | I8: 9.478637 | J8: 9.3026 | K8: 8.916166 | L8: 9.052803 | M8: 9.197401 | N8: 9.234192 | O8: -0.562471 | P8: 1 | Q8: 13.824965 | R8: 53.825072 | S8: 54.031959 | T8: 1.778526 | U8: 3.30427 | V8: 55.997796 | W8: 54.962208 | X8: 53.2896 | Y8: 185.96257 | Z8: 2.784781 | AA8: 44.62767 | AB8: 44.797767 | AC8: 1133 | AD8: 7.324869
A9: ALT (31.0.101.2115) | B9: 8 | C9: 36.977843 | D9: 185.67658 | E9: 307.20953 | F9: ja | G9: nein | H9: ja | I9: 9.237428 | J9: 9.176972 | K9: 9.2491 | L9: 9.19728 | M9: 9.243264 | N9: 9.1872 | O9: 0.011672 | P9: 7 | Q9: 15.29808 | R9: 54.178304 | S9: 54.4258 | T9: 1.75696 | U9: 3.242922 | V9: 56.59776 | W9: 55.449252 | X9: 54.571968 | Y9: 185.67658 | Z9: 2.798485 | AA9: 44.93504 | AB9: 45.2386 | AC9: 1156 | AD9: 7.217461
A10: ALT (31.0.101.2115) | B10: 9 | C10: 42.096342 | D10: 185.84072 | E10: 307.10989 | F10: ja | G10: nein | H10: ja | I10: 8.916174 | J10: 8.98356 | K10: 9.259862 | L10: 9.13968 | M10: 9.088018 | N10: 9.07872 | O10: 0.343688 | P10: 3 | Q10: 16.512 | R10: 54.085593 | S10: 54.227188 | T10: 1.279128 | U10: 2.365006 | V10: 56.15136 | W10: 55.260344 | X10: 53.352 | Y10: 185.84072 | Z10: 2.793507 | AA10: 44.997575 | AB10: 45.148468 | AC10: 1149 | AD10: 7.277965
A11: ALT (31.0.101.2115) | B11: 10 | C11: 47.199408 | D11: 185.84727 | E11: 306.18395 | F11: ja | G11: nein | H11: ja | I11: 9.332764 | J11: 9.33792 | K11: 9.093984 | L11: 9.167123 | M11: 9.213374 | N11: 9.22488 | O11: -0.23878 | P11: 3 | Q11: 14.933565 | R11: 54.163098 | S11: 54.45408 | T11: 1.67941 | U11: 3.100653 | V11: 56.8296 | W11: 55.119312 | X11: 54.289806 | Y11: 185.84727 | Z11: 2.798464 | AA11: 44.949724 | AB11: 45.2292 | AC11: 1161 | AD11: 7.195335
A12: MITTEL (31.0.101.2135) | B12: 1 | C12: 1.142831 | D12: 186.62488 | F12: ja | G12: nein | H12: ja | I12: 10.651241 | J12: 8.42568 | K12: 7.742854 | L12: 7.51212 | M12: 9.197047 | N12: 7.876072 | O12: -2.908387 | P12: 3 | Q12: 35.18319 | R12: 52.90871 | S12: 53.10648 | T12: 1.670382 | U12: 3.157103 | V12: 63.65184 | W12: 54.45408 | X12: 51.52896 | Y12: 186.62488 | Z12: 2.745257 | AA12: 43.711663 | AB12: 45.230408 | AC12: 951 | AD12: 8.578006
A13: MITTEL (31.0.101.2135) | B13: 2 | C13: 6.271573 | D13: 187.62651 | E13: 307.72456 | F13: ja | G13: ja | H13: ja | I13: 8.150762 | J13: 7.60464 | K13: 10.821391 | L13: 8.795018 | M13: 9.486077 | N13: 8.261991 | O13: 2.670629 | P13: 3 | Q13: 40.764318 | R13: 52.904609 | S13: 53.152644 | T13: 2.291365 | U13: 4.331125 | V13: 57.67152 | W13: 54.650164 | X13: 51.964336 | Y13: 187.62651 | Z13: 2.76278 | AA13: 43.418532 | AB13: 44.890653 | AC13: 938 | AD13: 8.684933
A14: MITTEL (31.0.101.2135) | B14: 3 | C14: 11.415525 | D14: 185.73344 | E14: 308.63711 | F14: ja | G14: nein | H14: ja | I14: 8.140231 | J14: 7.94136 | K14: 8.387759 | L14: 8.15796 | M14: 8.263995 | N14: 8.0784 | O14: 0.247527 | P14: 2 | Q14: 13.56864 | R14: 53.366874 | S14: 53.43696 | T14: 2.134197 | U14: 3.999104 | V14: 61.944 | W14: 55.185296 | X14: 53.090982 | Y14: 185.73344 | Z14: 2.757988 | AA14: 45.102879 | AB14: 45.35856 | AC14: 957 | AD14: 8.753514
A15: MITTEL (31.0.101.2135) | B15: 4 | C15: 16.547327 | D15: 185.81304 | E15: 307.90809 | F15: ja | G15: nein | H15: ja | I15: 7.891929 | J15: 7.84836 | K15: 8.344662 | L15: 8.188578 | M15: 8.118296 | N15: 8.018432 | O15: 0.452733 | P15: 1 | Q15: 13.2192 | R15: 53.15146 | S15: 53.39544 | T15: 1.738188 | U15: 3.270254 | V15: 55.62144 | W15: 54.512928 | X15: 51.83136 | Y15: 185.81304 | Z15: 2.74756 | AA15: 45.033164 | AB15: 45.377009 | AC15: 976 | AD15: 8.573513
A16: MITTEL (31.0.101.2135) | B16: 5 | C16: 21.659985 | D16: 185.64969 | E16: 306.7595 | F16: ja | G16: nein | H16: ja | I16: 7.9202 | J16: 7.78428 | K16: 8.659237 | L16: 8.588035 | M16: 8.289718 | N16: 8.133027 | O16: 0.739037 | P16: 0 | Q16: 13.24896 | R16: 53.14168 | S16: 53.37504 | T16: 1.545828 | U16: 2.908881 | V16: 55.56672 | W16: 54.5194 | X16: 52.24272 | Y16: 185.64969 | Z16: 2.742627 | AA16: 44.851961 | AB16: 45.242013 | AC16: 963 | AD16: 8.64668
A17: MITTEL (31.0.101.2135) | B17: 6 | C17: 26.789333 | D17: 185.72988 | E17: 307.76087 | F17: ja | G17: nein | H17: ja | I17: 8.081882 | J17: 8.080248 | K17: 7.937385 | L17: 7.637742 | M17: 8.009634 | N17: 8.017708 | O17: -0.144497 | P17: 1 | Q17: 14.255873 | R17: 53.224609 | S17: 53.43192 | T17: 1.930704 | U17: 3.627466 | V17: 60.99228 | W17: 55.069032 | X17: 52.215542 | Y17: 185.72988 | Z17: 2.75009 | AA17: 45.214975 | AB17: 45.414212 | AC17: 959 | AD17: 8.756801
A18: MITTEL (31.0.101.2135) | B18: 7 | C18: 31.921341 | D18: 185.9938 | E18: 307.92047 | F18: ja | G18: nein | H18: ja | I18: 7.898133 | J18: 7.881664 | K18: 7.899253 | L18: 7.666812 | M18: 7.898693 | N18: 7.75779 | O18: 0.00112 | P18: 0 | Q18: 12.64896 | R18: 53.051459 | S18: 53.3532 | T18: 1.841118 | U18: 3.470438 | V18: 55.724502 | W18: 54.170848 | X18: 51.72 | Y18: 185.9938 | Z18: 2.74531 | AA18: 45.152766 | AB18: 45.59541 | AC18: 948 | AD18: 8.858792
A19: MITTEL (31.0.101.2135) | B19: 8 | C19: 37.0583 | D19: 184.69513 | E19: 308.21754 | F19: ja | G19: nein | H19: ja | I19: 7.755428 | J19: 7.881532 | K19: 8.346672 | L19: 8.407888 | M19: 8.05105 | N19: 8.111819 | O19: 0.591244 | P19: 2 | Q19: 13.020084 | R19: 53.109639 | S19: 53.26582 | T19: 1.233506 | U19: 2.322566 | V19: 55.243225 | W19: 54.211227 | X19: 52.175295 | Y19: 184.69513 | Z19: 2.726278 | AA19: 45.058588 | AB19: 45.154001 | AC19: 972 | AD19: 8.561833
A20: MITTEL (31.0.101.2135) | B20: 9 | C20: 42.17429 | D20: 185.79126 | E20: 306.95944 | F20: ja | G20: nein | H20: ja | I20: 7.941778 | J20: 7.712482 | K20: 7.918632 | L20: 7.788288 | M20: 7.930205 | N20: 7.728147 | O20: -0.023146 | P20: 2 | Q20: 14.4096 | R20: 53.140264 | S20: 53.430664 | T20: 1.855495 | U20: 3.491694 | V20: 55.947427 | W20: 54.730752 | X20: 53.47308 | Y20: 185.79126 | Z20: 2.746888 | AA20: 45.210059 | AB20: 45.702517 | AC20: 962 | AD20: 8.731428
A21: MITTEL (31.0.101.2135) | B21: 10 | C21: 47.293105 | D21: 186.7252 | E21: 307.12887 | F21: ja | G21: nein | H21: ja | I21: 7.560388 | J21: 7.381107 | K21: 8.467137 | L21: 8.378124 | M21: 8.013762 | N21: 7.910343 | O21: 0.906749 | P21: 1 | Q21: 13.9524 | R21: 52.961753 | S21: 53.350362 | T21: 2.241965 | U21: 4.233178 | V21: 57.19896 | W21: 54.341403 | X21: 53.141946 | Y21: 186.7252 | Z21: 2.752276 | AA21: 44.947991 | AB21: 45.440019 | AC21: 961 | AD21: 8.73353
A22: NEU (31.0.101.2141) | B22: 1 | C22: 1.09317 | D22: 186.64612 | F22: ja | G22: ja | H22: ja | I22: 12.13915 | J22: 8.716598 | K22: 8.557753 | L22: 7.546447 | M22: 10.348452 | N22: 7.954177 | O22: -3.581396 | P22: 5 | Q22: 43.1244 | R22: 52.943579 | S22: 52.985416 | T22: 2.160168 | U22: 4.080132 | V22: 62.816424 | W22: 54.727456 | X22: 52.629192 | Y22: 186.64612 | Z22: 2.748731 | AA22: 42.595128 | AB22: 45.031239 | AC22: 923 | AD22: 8.613451
A23: NEU (31.0.101.2141) | B23: 2 | C23: 6.238782 | D23: 185.73116 | E23: 308.73667 | F23: ja | G23: ja | H23: ja | I23: 9.028005 | J23: 8.127812 | K23: 13.071523 | L23: 9.3651 | M23: 11.049764 | N23: 8.576359 | O23: 4.043519 | P23: 3 | Q23: 43.327944 | R23: 53.540438 | S23: 53.464576 | T23: 2.518958 | U23: 4.704777 | V23: 63.8616 | W23: 57.112375 | X23: 52.789845 | Y23: 185.73116 | Z23: 2.766543 | AA23: 42.490673 | AB23: 44.888217 | AC23: 954 | AD23: 8.272371
A24: NEU (31.0.101.2141) | B24: 3 | C24: 11.352576 | D24: 185.69695 | E24: 306.82768 | F24: ja | G24: nein | H24: ja | I24: 8.514878 | J24: 8.270276 | K24: 8.642742 | L24: 8.533752 | M24: 8.57881 | N24: 8.376486 | O24: 0.127864 | P24: 4 | Q24: 14.698108 | R24: 53.384918 | S24: 53.4576 | T24: 1.774853 | U24: 3.324635 | V24: 61.15824 | W24: 54.949073 | X24: 51.83136 | Y24: 185.69695 | Z24: 2.755985 | AA24: 44.806109 | AB24: 45.081114 | AC24: 965 | AD24: 8.622132
A25: NEU (31.0.101.2141) | B25: 4 | C25: 16.481627 | D25: 186.71001 | E25: 307.74308 | F25: ja | G25: nein | H25: ja | I25: 8.111393 | J25: 7.92468 | K25: 8.463121 | L25: 8.445316 | M25: 8.287257 | N25: 8.161465 | O25: 0.351728 | P25: 1 | Q25: 13.879668 | R25: 53.127947 | S25: 53.33824 | T25: 2.064328 | U25: 3.885579 | V25: 62.916183 | W25: 54.85392 | X25: 51.75504 | Y25: 186.71001 | Z25: 2.76006 | AA25: 44.840691 | AB25: 45.176775 | AC25: 951 | AD25: 8.803581
A26: NEU (31.0.101.2141) | B26: 5 | C26: 21.610767 | D26: 185.58043 | E26: 307.74838 | F26: ja | G26: nein | H26: ja | I26: 8.047008 | J26: 7.89888 | K26: 8.133787 | L26: 7.973123 | M26: 8.090397 | N26: 7.95727 | O26: 0.086779 | P26: 1 | Q26: 13.904352 | R26: 53.176139 | S26: 53.38278 | T26: 1.418369 | U26: 2.667304 | V26: 57.39415 | W26: 54.480556 | X26: 52.2648 | Y26: 185.58043 | Z26: 2.74286 | AA26: 45.085741 | AB26: 45.42551 | AC26: 969 | AD26: 8.634707
A27: NEU (31.0.101.2141) | B27: 6 | C27: 26.741877 | D27: 185.81784 | E27: 307.86661 | F27: ja | G27: nein | H27: ja | I27: 7.792365 | J27: 7.542336 | K27: 8.385899 | L27: 8.14272 | M27: 8.089132 | N27: 7.87848 | O27: 0.593534 | P27: 1 | Q27: 13.89696 | R27: 53.288747 | S27: 53.39544 | T27: 1.821156 | U27: 3.417524 | V27: 59.43 | W27: 55.201344 | X27: 51.743664 | Y27: 185.81784 | Z27: 2.754166 | AA27: 45.199615 | AB27: 45.51696 | AC27: 948 | AD27: 8.859594
A28: NEU (31.0.101.2141) | B28: 7 | C28: 31.876266 | D28: 185.99142 | E28: 308.06335 | F28: ja | G28: nein | H28: ja | I28: 7.798911 | J28: 7.832169 | K28: 8.213036 | L28: 7.87848 | M28: 8.005973 | N28: 7.87848 | O28: 0.414125 | P28: 0 | Q28: 13.87488 | R28: 53.015039 | S28: 53.31312 | T28: 1.951445 | U28: 3.680927 | V28: 55.332 | W28: 54.175229 | X28: 51.806565 | Y28: 185.99142 | Z28: 2.743764 | AA28: 45.009066 | AB28: 45.43464 | AC28: 943 | AD28: 8.877307
A29: NEU (31.0.101.2141) | B29: 8 | C29: 36.980927 | D29: 185.76642 | E29: 306.27965 | F29: ja | G29: nein | H29: ja | I29: 7.969583 | J29: 7.77096 | K29: 8.287488 | L29: 8.157248 | M29: 8.128535 | N29: 8.050288 | O29: 0.317905 | P29: 0 | Q29: 14.2672 | R29: 53.271356 | S29: 53.39544 | T29: 1.595273 | U29: 2.994617 | V29: 57.72312 | W29: 54.661536 | X29: 52.05984 | Y29: 185.76642 | Z29: 2.751272 | AA29: 45.142821 | AB29: 45.345152 | AC29: 942 | AD29: 8.902357
A30: NEU (31.0.101.2141) | B30: 9 | C30: 42.096699 | D30: 185.92176 | E30: 306.94628 | F30: ja | G30: nein | H30: ja | I30: 7.843114 | J30: 7.77072 | K30: 8.269245 | L30: 8.231427 | M30: 8.056179 | N30: 7.988909 | O30: 0.426131 | P30: 1 | Q30: 13.937994 | R30: 53.191089 | S30: 53.41488 | T30: 1.666238 | U30: 3.13255 | V30: 56.06448 | W30: 54.705696 | X30: 52.632 | Y30: 185.92176 | Z30: 2.74899 | AA30: 45.13491 | AB30: 45.425971 | AC30: 963 | AD30: 8.713979
A31: NEU (31.0.101.2141) | B31: 10 | C31: 47.233217 | D31: 185.8899 | E31: 308.19111 | F31: ja | G31: nein | H31: ja | I31: 8.06065 | J31: 8.09244 | K31: 7.995927 | L31: 8.08314 | M31: 8.028288 | N31: 8.08314 | O31: -0.064723 | P31: 1 | Q31: 14.066688 | R31: 53.20098 | S31: 53.4768 | T31: 1.713117 | U31: 3.220085 | V31: 55.933208 | W31: 54.442768 | X31: 51.804396 | Y31: 185.8899 | Z31: 2.750959 | AA31: 45.172692 | AB31: 45.39366 | AC31: 960 | AD31: 8.747028

Sheet Tests
A1: Statistische Tests zwischen den Treibern
A2: Berechnet in Python mit scipy: Kruskal-Wallis, Alexander-Govern (Welch-ANOVA), Welch-t-Test, Mann-Whitney-U; paarweise p-Werte Holm-korrigiert. KI der Differenz nach Welch-Satterthwaite. Hedges g = Effektstärke.
A4: Kennzahl | B4: Kruskal-Wallis p | C4: Welch-ANOVA p
A5: Mehrverbrauch Delta | B5: 0.48801001 | C5: 0.77990714
A6: Last Ø | B6: 3.9545268e-05 | C6: 1.2730217e-07
A7: Leerlauf Ø | B7: 0.0070219826 | C7: 0.00031017781
A8: Effizienz (J je Score-Punkt) | B8: 5.5094999e-05 | C8: 4.8285396e-24
A10: Kennzahl | B10: Treiber A | C10: Treiber B | D10: n A | E10: n B | F10: Mittel A | G10: Mittel B | H10: Differenz B − A | I10: relativ [%] | J10: KI unten | K10: KI oben | L10: p Welch (Holm) | M10: p MWU (Holm) | N10: Hedges g | O10: Effekt | P10: signifikant (5 %)
A11: delta | B11: ALT (31.0.101.2115) | C11: MITTEL (31.0.101.2135) | D11: 10 | E11: 10 | F11: 44.80471 | G11: 44.770258 | H11: -0.034452076 | I11: -0.076893871 | J11: -0.52750435 | K11: 0.4586002 | L11: 1 | M11: 0.92246837 | N11: -0.064617867 | O11: vernachlässigbar | P11: =IF(L11="","",IF(L11<0.05,"ja","nein"))
A12: delta | B12: ALT (31.0.101.2115) | C12: NEU (31.0.101.2141) | D12: 10 | E12: 10 | F12: 44.80471 | G12: 44.547745 | H12: -0.25696546 | I12: -0.57352331 | J12: -1.0343471 | K12: 0.52041622 | L12: 1 | M12: 0.92246837 | N12: -0.3131114 | O12: klein | P12: =IF(L12="","",IF(L12<0.05,"ja","nein"))
A13: delta | B13: MITTEL (31.0.101.2135) | C13: NEU (31.0.101.2141) | D13: 10 | E13: 10 | F13: 44.770258 | G13: 44.547745 | H13: -0.22251338 | I13: -0.49701161 | J13: -1.063822 | K13: 0.61879526 | L13: 1 | M13: 0.92246837 | N13: -0.24164641 | O13: klein | P13: =IF(L13="","",IF(L13<0.05,"ja","nein"))
A14: load_mean | B14: ALT (31.0.101.2115) | C14: MITTEL (31.0.101.2135) | D14: 10 | E14: 10 | F14: 54.111 | G14: 53.096106 | H14: -1.014894 | I14: -1.8755781 | J14: -1.2215292 | K14: -0.80825887 | L14: 1.5964737e-07 | M14: 0.00054801537 | N14: -4.51634 | O14: groß | P14: =IF(L14="","",IF(L14<0.05,"ja","nein"))
A15: load_mean | B15: ALT (31.0.101.2115) | C15: NEU (31.0.101.2141) | D15: 10 | E15: 10 | F15: 54.111 | G15: 53.214023 | H15: -0.89697633 | I15: -1.6576599 | J15: -1.1110672 | K15: -0.68288545 | L15: 3.6852616e-07 | M15: 0.00054801537 | N15: -3.8171234 | O15: groß | P15: =IF(L15="","",IF(L15<0.05,"ja","nein"))
A16: load_mean | B16: MITTEL (31.0.101.2135) | C16: NEU (31.0.101.2141) | D16: 10 | E16: 10 | F16: 53.096106 | G16: 53.214023 | H16: 0.11791771 | I16: 0.22208353 | J16: -0.031913571 | K16: 0.26774898 | L16: 0.1153686 | M16: 0.10410989 | N16: 0.70968152 | O16: mittel | P16: =IF(L16="","",IF(L16<0.05,"ja","nein"))
A17: idle_mean | B17: ALT (31.0.101.2115) | C17: MITTEL (31.0.101.2135) | D17: 10 | E17: 10 | F17: 9.3062896 | G17: 8.3258477 | H17: -0.98044197 | I17: -10.535262 | J17: -1.3852131 | K17: -0.57567084 | L17: 0.00078294959 | M17: 0.010831543 | N17: -2.2930851 | O17: groß | P17: =IF(L17="","",IF(L17<0.05,"ja","nein"))
A18: idle_mean | B18: ALT (31.0.101.2115) | C18: NEU (31.0.101.2141) | D18: 10 | E18: 10 | F18: 9.3062896 | G18: 8.6662788 | H18: -0.64001088 | I18: -6.8771863 | J18: -1.428525 | K18: 0.14850328 | L18: 0.20004518 | M18: 0.051496162 | N18: -0.78112217 | O18: mittel | P18: =IF(L18="","",IF(L18<0.05,"ja","nein"))
A19: idle_mean | B19: MITTEL (31.0.101.2135) | C19: NEU (31.0.101.2141) | D19: 10 | E19: 10 | F19: 8.3258477 | G19: 8.6662788 | H19: 0.34043109 | I19: 4.088846 | J19: -0.49724811 | K19: 1.1781103 | L19: 0.39662905 | M19: 0.38467306 | N19: 0.37514917 | O19: klein | P19: =IF(L19="","",IF(L19<0.05,"ja","nein"))
A20: eff | B20: ALT (31.0.101.2115) | C20: MITTEL (31.0.101.2135) | D20: 10 | E20: 10 | F20: 7.2119229 | G20: 8.687903 | H20: 1.4759801 | I20: 20.465834 | J20: 1.3973654 | K20: 1.5545948 | L20: 8.9919819e-17 | M20: 0.00054801537 | N20: 17.06836 | O20: groß | P20: =IF(L20="","",IF(L20<0.05,"ja","nein"))
A21: eff | B21: ALT (31.0.101.2115) | C21: NEU (31.0.101.2141) | D21: 10 | E21: 10 | F21: 7.2119229 | G21: 8.7046507 | H21: 1.4927278 | I21: 20.698056 | J21: 1.3557694 | K21: 1.6296862 | L21: 1.1518769e-10 | M21: 0.00054801537 | N21: 10.253588 | O21: groß | P21: =IF(L21="","",IF(L21<0.05,"ja","nein"))
A22: eff | B22: MITTEL (31.0.101.2135) | C22: NEU (31.0.101.2141) | D22: 10 | E22: 10 | F22: 8.687903 | G22: 8.7046507 | H22: 0.01674769 | I22: 0.19277022 | J22: -0.12602567 | K22: 0.15952105 | L22: 0.80456261 | M22: 0.47267559 | N22: 0.10807994 | O22: vernachlässigbar | P22: =IF(L22="","",IF(L22<0.05,"ja","nein"))

Sheet Trend
A1: Entwicklung über die Zyklen (lineare Regression je Treiber)
A2: Berechnet in Python (scipy.stats.linregress). p < 0,05 und merkliche Summe über den Lauf deuten auf Aufwärm- oder Temperatureffekte.
A4: Treiber | B4: Größe | C4: Steigung je Zyklus [W] | D4: Summe über Lauf [W] | E4: R² | F4: p | G4: Zyklus 1 − übrige [W]
A5: ALT (31.0.101.2115) | B5: Last Ø | C5: 0.021653542 | D5: 0.19488188 | E5: 0.059988627 | F5: 0.495225 | G5: -0.69127686
A6: ALT (31.0.101.2115) | B6: Delta | C6: 0.046945043 | D6: 0.42250539 | E6: 0.20044335 | F6: 0.19446113 | G6: -0.81204037
A7: ALT (31.0.101.2115) | B7: Leerlauf Ø | C7: -0.025291501 | D7: -0.22762351 | E7: 0.20843967 | F7: 0.18472037 | G7: 0.1207635
A8: MITTEL (31.0.101.2135) | B8: Last Ø | C8: 0.0037801779 | D8: 0.034021601 | E8: 0.0062397385 | F8: 0.82827913 | G8: -0.20821761
A9: MITTEL (31.0.101.2135) | B9: Delta | C9: 0.1464728 | D9: 1.3182552 | E9: 0.46745013 | F9: 0.029259509 | G9: -1.1762171
A10: MITTEL (31.0.101.2135) | B10: Leerlauf Ø | C10: -0.14269262 | D10: -1.2842336 | E10: 0.60747217 | F10: 0.0078617054 | G10: 0.96799949
A11: NEU (31.0.101.2141) | B11: Last Ø | C11: -0.0055924817 | D11: -0.050332335 | E11: 0.0096676148 | F11: 0.7869835 | G11: -0.30049343
A12: NEU (31.0.101.2141) | B12: Delta | C12: 0.26672904 | D12: 2.4005614 | E12: 0.57467443 | F12: 0.01105956 | G12: -2.1695743
A13: NEU (31.0.101.2141) | B13: Leerlauf Ø | C13: -0.27232152 | D13: -2.4508937 | E13: 0.56486174 | F13: 0.012192082 | G13: 1.8690809

Sheet Info
A1: Messaufbau, Parameter und Datenqualität
A3: Benchmark | B3: FurMark (Intel UHD 630)
A4: Erwartete Lastdauer [s] | B4: 180
A5: Erwarteter Leerlauf je Seite [s] | B5: 60
A6: Erwartete Zyklen | B6: 10
A7: Lastfenster | B7: vollständiges Plateau je Durchlauf, vom ersten bis zum letzten Messwert über der Schwelle (Median 185.8 s, 184.6 bis 187.6 s)
A8: Plateauflanken | B8: Beginn über drei Rohwerte bestätigt (zählen mit), Ende = letzter Wert über der Schwelle
A9: Abstand Leerlauffenster zu Flanken [s] | B9: 5
A10: Länge Leerlauffenster [s] | B10: 50
A11: Vergleichsbasis | B11: ALT (31.0.101.2115)
A14: Treiber | B14: Datei | C14: Messwerte | D14: Dauer [min] | E14: Δt Median [s] | F14: größte Lücke [s] | G14: Schwelle [W] | H14: Leerlaufniveau [W] | I14: Lastniveau [W] | J14: Trennschärfe | K14: Lastphasen erkannt
A15: ALT (31.0.101.2115) | B15: Messung_gpu_alt.log | C15: 3094 | D15: 52.050828 | E15: 1.009692 | F15: 1.037369 | G15: 31.783047 | H15: 9.2817378 | I15: 54.284356 | J15: 65.971447 | K15: 10
A16: MITTEL (31.0.101.2135) | B16: Messung_gpu_mittel.log | C16: 3090 | D16: 51.970792 | E16: 1.009163 | F16: 1.045102 | G16: 30.728533 | H16: 8.1288979 | I16: 53.328169 | J16: 58.660842 | K16: 10
A17: NEU (31.0.101.2141) | B17: Messung_gpu_neu.log | C17: 3070 | D17: 51.644646 | E17: 1.009562 | F17: 1.047759 | G17: 30.789109 | H17: 8.2322382 | I17: 53.345979 | J17: 58.016203 | K17: 10
A19: Hinweis | B19: Die Zyklen eines Treibers stammen aus einer Sitzung und bilden die Streuung von Zyklus zu Zyklus ab, nicht die zwischen Messtagen oder Neuinstallationen.
